Workbook

Sheet 📞 Call Tracker
A1: AccountNumber | B1: Associate | C1: DateCalled | D1: VM | E1: Outcome | F1: Notes | G1: Priority | H1: CustomerName | I1: City | J1: RatePlan | K1: MEPStatus | L1: Issue
A2: 5411325149 | B2: Michelle | C2: 46025 | D2: YES | G2: Called | H2: Coudriet, Lise | I2: Goodyear | J2: R-BASICL | K2: Not on Best Plan | L2: Will cause hardships
A3: 5372102528 | B3: Michelle | C3: 46046 | D3: NO | E3: Utility Assistance | G3: Called | H3: Price, Shannon | I3: Phoenix | J3: R3-47 | K3: Not on Best Plan | L3: Form letter
A4: 4300170000 | B4: Joaquin | C4: 46046 | D4: YES | F4: STOPPED S-A 2025-06-04 to 2025-11-03 | G4: Called | H4: Bryant, Shelby | I4: Phoenix | J4: RTOUE47 | K4: Not on Best Plan | L4: Opposed, unfair burden on families and seniors
A5: 0356005964 | B5: Joaquin | C5: 46046 | D5: NO | E5: General Education | F5: OFFER OPTION TO LOWER BILL | G5: Called | H5: Santoyo, Ashlee | I5: Surprise | J5: RTOUE47 | K5: Not on Best Plan | L5: Form letter
A6: 6846061000 | B6: Joaquin | C6: 46039 | D6: YES | G6: Called | H6: McCloud, Jason | I6: Surprise | J6: RTOUE47 | K6: Not on Best Plan | L6: Unchecked greed
A7: 0902311000 | B7: Joaquin | C7: 46025 | D7: YES | F7: LEFT VOICE MAIL | G7: Called | H7: Inman, Bonnie | I7: Phoenix | J7: RTOUE47 | K7: Not on Best Plan | L7: Form letter
A8: 4528501000 | B8: Joaquin | C8: 46025 | F8: LEFT VOICE MAIL | G8: Called | H8: Josselyn, Anne | I8: Sun City | J8: R-BASIC | K8: Not on Best Plan | L8: Opposed
A9: 2060349043 | B9: Joaquin | C9: 46025 | D9: NO | F9: VOICE MAIL WAS FULL | G9: Called | H9: Ramos, Mercedes | I9: Yuma | J9: RCPw/R3-47 | K9: Not on Best Plan | L9: Extremely expensive
A10: 4573855715 | B10: Joaquin | C10: 45997 | D10: YES | F10: NO E3 ON ACCT IS ON PAYMENT ARRANGEMENT | G10: Called | H10: Vandenberg, Taylor | I10: Phoenix | J10: RTOUE47 | K10: Not on Best Plan | L10: Opposed-Terrible idea for Arizonans
A11: 9340701000 | B11: Joaquin | C11: 46039 | D11: YES | G11: Called | H11: Pablo, Jerome | I11: Buckeye | J11: RCPw/RTOUE47 | K11: Not on Best Plan | L11: Power is already expensive
A12: 5596059869 | B12: Joaquin | C12: 46032 | E12: Other (fill in) | F12: CALLER HUNG UP | G12: Called | H12: Youngker, Virginia | I12: Scottsdale | J12: RTOUE47 | K12: Not on Best Plan | L12: Form Letter: Enough is enough! You must reject the latest 14% rate hikes by APS and TEP
A13: 6013821000 | B13: Joaquin | C13: 46032 | D13: YES | F13: BETTER RATE FIXXED ENERGY PLAN | G13: Called | H13: Haden, Scott | I13: Phoenix | J13: RTOUE47 | K13: Not on Best Plan | L13: Form Letter: Enough is enough! You must reject the latest 14% rate hikes by APS and TEP
A14: 1205900735 | B14: Joaquin | C14: 46032 | D14: YES | F14: LEFT VOICE MESSAGE | G14: Called | H14: Summons, Miranda | I14: Phoenix | J14: R-BASIC | K14: Not on Best Plan | L14: I am against the rate increase
A15: 1039090000 | B15: Joaquin | C15: 46032 | D15: YES | F15: LEFT VOICE MESSAGE | G15: Called | H15: Byman, Rachel | I15: Phoenix | J15: R3-47 | K15: Not on Best Plan | L15: Form Letter: Enough is enough! You must reject the latest 14% rate hikes by APS and TEP
A16: 6003957639 | B16: Joaquin | C16: 46032 | D16: YES | F16: BETTER PLAN TIME OF WITH DEMAND | G16: Called | H16: Hernandez, Maria | I16: Youngtown | J16: RTOUE47 | K16: Not on Best Plan | L16: Form Letter: Enough is enough! You must reject the latest 14% rate hikes by APS and TEP
A17: 3304816868 | B17: Joaquin | C17: 46032 | E17: Rate Change | F17: ED ON PLANS TO HELP SAVE & REBATE INFO | G17: Called | H17: Curds, Diana | I17: Phoenix | J17: RTOUE47 | K17: Not on Best Plan | L17: I oppose the rate hike. Bills are high enough. No one can survive paying $650.
A18: 0509660000 | B18: Joaquin | C18: 46018 | D18: NO | E18: General Education | G18: Called | H18: Posey, Michael | I18: Buckeye | J18: RTOUE47 | K18: Not on Best Plan | L18: Form Letter: Enough is enough! You must reject the latest 14% rate hikes by APS e TEP
A19: 7401033818 | G19: P1 | H19: Cearns, Katharine | I19: Yuma | J19: R-2 | K19: Not on Best Plan | L19: Form Letter: Enough is enough! You must reject the latest 14% rate hikes by APS e TEP
A20: 2947560540 | G20: P1 | H20: Apolinar, Alexia | I20: Goodyear | J20: RCPw/TOUE47 | K20: Not on Best Plan | L20: Oppose -rate was just increased less than 2 years ago
A21: 3110727023 | G21: P1 | H21: Downs, Jodi | I21: Glendale | J21: R-BASIC | K21: Not on Best Plan | L21: On a budget and already working 2 jobs to make ends meet, the price hike is nothing but greed.
A22: 8998382174 | G22: P1 | H22: Andujar, Elizabeth | I22: Phoenix | J22: R3-47 | K22: Not on Best Plan | L22: I believe that aps should lower the cost because not all of us has the funds to keep paying a lot of money
A23: 7201057343 | G23: P1 | H23: Arends, TeNisha | I23: Surprise | J23: R3-47 | K23: Not on Best Plan | L23: We have the sun at our disposal. Why isn't APS taking advantage of that to help the consumers that need their services
A24: 3323516971 | G24: P1 | H24: Bugenski, Jennifer | I24: Flagstaff | J24: RTOUE47 | K24: Not on Best Plan | L24: I'm against the rate hike we are expensive enough
A25: 4067480384 | G25: P1 | H25: King, Melvinna | I25: Avondale | J25: 0 | K25: Not on Best Plan | L25: it's time to humble oneself because God is coming to humble those who feel they are in control
A26: 0339264588 | G26: P1 | H26: Gajon, Anaisabel | I26: Yuma | J26: RTOUE47 | K26: Not on Best Plan | L26: Everything is too expensive. It is impossible to afford electricity in this heat as is,
A27: 9532631000 | G27: P1 | H27: Valladares, Rosalva | I27: Phoenix | J27: RTOUE47 | K27: Not on Best Plan | L27: If APS really cares about its customers look into blocking these data centers from moving to Arizona
A28: 0310740000 | G28: P1 | H28: Bean, Jodi | I28: Wittmann | J28: RTOUE47 | K28: Not on Best Plan | L28: I dent think APS needs another 14% rate hike people are barely making ends meet.
A29: 3049940000 | B29: Michelle | C29: 46067 | D29: YES | G29: Called | H29: Rizzi, Carol | I29: Unknown | J29: R-XS | K29: Not on Best Plan | L29: Opposed
A30: 2779220471 | B30: Michelle | C30: 46060 | D30: YES | F30: SOLAR ACCT | G30: Called | H30: Charapata, Maxwell | I30: Phoenix | J30: RTOUE47 | K30: Not on Best Plan | L30: Opposed
A31: 6635023227 | B31: Michelle | C31: 46032 | D31: NO | E31: Other (fill in) | F31: SOLAR ACCT | G31: Called | H31: Howell, Chris | I31: Surprise | J31: RTOUE47 | K31: Not on Best Plan | L31: Form letter
A32: 6924836428 | B32: Michelle | C32: 46053 | D32: NO | E32: General Education | G32: Called | H32: Scharroo, George | I32: Phoenix | J32: R3-47 | K32: Not on Best Plan | L32: Opposed
A33: 7035930772 | B33: Michelle | C33: 46053 | D33: YES | G33: Called | H33: Farr, Amanda | I33: Phoenix | J33: RTOUE47 | K33: Not on Best Plan | L33: Form letter
A34: 4659820000 | B34: Joaquin | C34: 46018 | D34: YES | G34: Called | H34: Norton, Colin | I34: Phoenix | J34: RTOUE47 | K34: Not on Best Plan | L34: Form letter
A35: 7477798096 | B35: Michelle | C35: 46053 | D35: YES | G35: Called | H35: Bergstrom, Shailey | I35: Phoenix | J35: R-BASICL | K35: Not on Best Plan | L35: Apt electric bill is as high as her parent home in Tucson
A36: 2605161000 | B36: Michelle | C36: 46053 | D36: YES | F36: LEFT VM | G36: Called | H36: Rogers, Richard | I36: Flagstaff | J36: R-BASIC | K36: Not on Best Plan | L36: Opposed
A37: 1560131000 | B37: Joaquin | C37: 46018 | D37: NO | G37: Called | H37: Gutierrez, Francisco | I37: Yuma | J37: RTOUE47 | K37: Not on Best Plan | L37: Form letter
A38: 4557041000 | B38: Michelle | C38: 46032 | D38: NO | E38: General Education | F38: SOLAR ACCT | G38: Called | H38: Mohapatra, Sangram | I38: Peoria | J38: RTOUE47 | K38: Not on Best Plan | L38: Form letter
A39: 7001761000 | B39: Michelle | C39: 46039 | D39: YES | F39: SOLAR ACCT | G39: Called | H39: Gurram , Tanooj Kumar Reddy | I39: Peoria | J39: RTOUE47 | K39: Not on Best Plan | L39: Form letter
A40: 5849875191 | B40: Michelle | C40: 46074 | D40: NO | E40: General Education | G40: Called | H40: Crowley, Kendell | I40: Phoenix | J40: RTOUE47 | K40: Not on Best Plan | L40: Form letter
...

Sheet Summary
B2: RATE CASE OUTREACH — EXECUTIVE SUMMARY
B4: Total Docketed | C4: Callable | D4: Contacted | E4: Remaining | F4: Progress | G4: VMs Left
B5: =COUNTA('Docketed Comments'!B2:B1949) -> 1946 | C5: {=SUMPRODUCT(('Call Queue'!H2:H1310<>"")*1)} -> 1309 | D5: =COUNTA('📞 Call Tracker'!B2:B2000) -> 399 | E5: =C5-D5 -> 910 | F5: =D5/C5 -> 0.30481283 | G5: =COUNTIF('📞 Call Tracker'!D2:D2000,"YES") -> 244
B6: Comments Filed | C6: Valid Customers | D6: Calls Made | E6: To Contact | F6: Completion | G6: Voicemails
B8: CUSTOMER INSIGHTS
B9: Not on MEP Left | C9: Payoff Balance Left | D9: On MEP | E9: Avg Calls/Week | F9: Unable to Locate | G9: Spoke With
B10: =COUNTIFS('Call Queue'!V2:V1310,"❌ Not on Best Plan")-COUNTIFS('Call Queue'!V2:V1310,"❌ Not on Best Plan",'Call Queue'!X2:X1310,">0") -> 229 | C10: =COUNTIFS('Call Queue'!N2:N1310,"<>No",'Call Queue'!N2:N1310,"<>")-COUNTIFS('Call Queue'!N2:N1310,"<>No",'Call Queue'!N2:N1310,"<>",'Call Queue'!X2:X1310,">0") -> 58 | D10: =COUNTIFS('Call Queue'!V2:V1310,"✅ On Best Plan")+COUNTIFS('Call Queue'!V2:V1310,"❄ Frozen Rate") -> 936 | E10: =IFERROR(ROUND(D5/MAX(1,(NETWORKDAYS(MIN('📞 Call Tracker'!C:C),TODAY())/5)),1),"-") -> 31.7 | F10: =COUNTIF('Docketed Comments'!H2:H1949,"Unable to Locate Acct")+COUNTBLANK('Docketed Comments'!H2:H1949) -> 478 | G10: =COUNTIF('📞 Call Tracker'!D2:D2000,"NO") -> 133
B11: =COUNTIFS('Call Queue'!V2:V1310,"❌ Not on Best Plan",'Call Queue'!X2:X1310,">0")&" of "&COUNTIFS('Call Queue'!V2:V1310,"❌ Not on Best Plan")&" contacted" -> 113 of 342 contacted | C11: =COUNTIFS('Call Queue'!N2:N1310,"<>No",'Call Queue'!N2:N1310,"<>",'Call Queue'!X2:X1310,">0")&" of "&COUNTIFS('Call Queue'!N2:N1310,"<>No",'Call Queue'!N2:N1310,"<>")&" contacted" -> 36 of 94 contacted | D11: Currently Enrolled | E11: Per Week | F11: Removed from Queue | G11: Conversations
B13: WEEKLY PERFORMANCE
B14: Week Of | C14: Total Calls | D14: VMs | E14: Contacts | F14: Michelle | G14: Joaquin
B15: {=IFERROR(_xlfn._xlws.SORT(_xlfn.UNIQUE(_xlfn._xlws.FILTER('📞 Call Tracker'!C2:C2000,'📞 Call Tracker'!C2:C2000>0))),"")} -> 45997 | C15: =IF(B15="","",COUNTIFS('📞 Call Tracker'!$C:$C,">="&B15,'📞 Call Tracker'!$C:$C,"<"&B15+1)) -> 46 | D15: =IF(B15="","",COUNTIFS('📞 Call Tracker'!$C:$C,">="&B15,'📞 Call Tracker'!$C:$C,"<"&B15+1,'📞 Call Tracker'!$D:$D,"YES")) -> 27 | E15: =IF(B15="","",COUNTIFS('📞 Call Tracker'!$C:$C,">="&B15,'📞 Call Tracker'!$C:$C,"<"&B15+1,'📞 Call Tracker'!$D:$D,"NO")) -> 9 | F15: =IF(B15="","",COUNTIFS('📞 Call Tracker'!$C:$C,">="&B15,'📞 Call Tracker'!$C:$C,"<"&B15+1,'📞 Call Tracker'!$B:$B,"Michelle")) -> 15 | G15: =IF(B15="","",COUNTIFS('📞 Call Tracker'!$C:$C,">="&B15,'📞 Call Tracker'!$C:$C,"<"&B15+1,'📞 Call Tracker'!$B:$B,"Joaquin")) -> 31
B16: 46011 | C16: =IF(B16="","",COUNTIFS('📞 Call Tracker'!$C:$C,">="&B16,'📞 Call Tracker'!$C:$C,"<"&B16+1)) -> 26 | D16: =IF(B16="","",COUNTIFS('📞 Call Tracker'!$C:$C,">="&B16,'📞 Call Tracker'!$C:$C,"<"&B16+1,'📞 Call Tracker'!$D:$D,"YES")) -> 19 | E16: =IF(B16="","",COUNTIFS('📞 Call Tracker'!$C:$C,">="&B16,'📞 Call Tracker'!$C:$C,"<"&B16+1,'📞 Call Tracker'!$D:$D,"NO")) -> 5 | F16: =IF(B16="","",COUNTIFS('📞 Call Tracker'!$C:$C,">="&B16,'📞 Call Tracker'!$C:$C,"<"&B16+1,'📞 Call Tracker'!$B:$B,"Michelle")) -> 0 | G16: =IF(B16="","",COUNTIFS('📞 Call Tracker'!$C:$C,">="&B16,'📞 Call Tracker'!$C:$C,"<"&B16+1,'📞 Call Tracker'!$B:$B,"Joaquin")) -> 26
B17: 46018 | C17: =IF(B17="","",COUNTIFS('📞 Call Tracker'!$C:$C,">="&B17,'📞 Call Tracker'!$C:$C,"<"&B17+1)) -> 11 | D17: =IF(B17="","",COUNTIFS('📞 Call Tracker'!$C:$C,">="&B17,'📞 Call Tracker'!$C:$C,"<"&B17+1,'📞 Call Tracker'!$D:$D,"YES")) -> 4 | E17: =IF(B17="","",COUNTIFS('📞 Call Tracker'!$C:$C,">="&B17,'📞 Call Tracker'!$C:$C,"<"&B17+1,'📞 Call Tracker'!$D:$D,"NO")) -> 7 | F17: =IF(B17="","",COUNTIFS('📞 Call Tracker'!$C:$C,">="&B17,'📞 Call Tracker'!$C:$C,"<"&B17+1,'📞 Call Tracker'!$B:$B,"Michelle")) -> 2 | G17: =IF(B17="","",COUNTIFS('📞 Call Tracker'!$C:$C,">="&B17,'📞 Call Tracker'!$C:$C,"<"&B17+1,'📞 Call Tracker'!$B:$B,"Joaquin")) -> 9
B18: 46025 | C18: =IF(B18="","",COUNTIFS('📞 Call Tracker'!$C:$C,">="&B18,'📞 Call Tracker'!$C:$C,"<"&B18+1)) -> 37 | D18: =IF(B18="","",COUNTIFS('📞 Call Tracker'!$C:$C,">="&B18,'📞 Call Tracker'!$C:$C,"<"&B18+1,'📞 Call Tracker'!$D:$D,"YES")) -> 27 | E18: =IF(B18="","",COUNTIFS('📞 Call Tracker'!$C:$C,">="&B18,'📞 Call Tracker'!$C:$C,"<"&B18+1,'📞 Call Tracker'!$D:$D,"NO")) -> 6 | F18: =IF(B18="","",COUNTIFS('📞 Call Tracker'!$C:$C,">="&B18,'📞 Call Tracker'!$C:$C,"<"&B18+1,'📞 Call Tracker'!$B:$B,"Michelle")) -> 2 | G18: =IF(B18="","",COUNTIFS('📞 Call Tracker'!$C:$C,">="&B18,'📞 Call Tracker'!$C:$C,"<"&B18+1,'📞 Call Tracker'!$B:$B,"Joaquin")) -> 35
B19: 46032 | C19: =IF(B19="","",COUNTIFS('📞 Call Tracker'!$C:$C,">="&B19,'📞 Call Tracker'!$C:$C,"<"&B19+1)) -> 20 | D19: =IF(B19="","",COUNTIFS('📞 Call Tracker'!$C:$C,">="&B19,'📞 Call Tracker'!$C:$C,"<"&B19+1,'📞 Call Tracker'!$D:$D,"YES")) -> 13 | E19: =IF(B19="","",COUNTIFS('📞 Call Tracker'!$C:$C,">="&B19,'📞 Call Tracker'!$C:$C,"<"&B19+1,'📞 Call Tracker'!$D:$D,"NO")) -> 2 | F19: =IF(B19="","",COUNTIFS('📞 Call Tracker'!$C:$C,">="&B19,'📞 Call Tracker'!$C:$C,"<"&B19+1,'📞 Call Tracker'!$B:$B,"Michelle")) -> 4 | G19: =IF(B19="","",COUNTIFS('📞 Call Tracker'!$C:$C,">="&B19,'📞 Call Tracker'!$C:$C,"<"&B19+1,'📞 Call Tracker'!$B:$B,"Joaquin")) -> 16
B20: 46039 | C20: =IF(B20="","",COUNTIFS('📞 Call Tracker'!$C:$C,">="&B20,'📞 Call Tracker'!$C:$C,"<"&B20+1)) -> 28 | D20: =IF(B20="","",COUNTIFS('📞 Call Tracker'!$C:$C,">="&B20,'📞 Call Tracker'!$C:$C,"<"&B20+1,'📞 Call Tracker'!$D:$D,"YES")) -> 19 | E20: =IF(B20="","",COUNTIFS('📞 Call Tracker'!$C:$C,">="&B20,'📞 Call Tracker'!$C:$C,"<"&B20+1,'📞 Call Tracker'!$D:$D,"NO")) -> 9 | F20: =IF(B20="","",COUNTIFS('📞 Call Tracker'!$C:$C,">="&B20,'📞 Call Tracker'!$C:$C,"<"&B20+1,'📞 Call Tracker'!$B:$B,"Michelle")) -> 9 | G20: =IF(B20="","",COUNTIFS('📞 Call Tracker'!$C:$C,">="&B20,'📞 Call Tracker'!$C:$C,"<"&B20+1,'📞 Call Tracker'!$B:$B,"Joaquin")) -> 19
B21: 46046 | C21: =IF(B21="","",COUNTIFS('📞 Call Tracker'!$C:$C,">="&B21,'📞 Call Tracker'!$C:$C,"<"&B21+1)) -> 41 | D21: =IF(B21="","",COUNTIFS('📞 Call Tracker'!$C:$C,">="&B21,'📞 Call Tracker'!$C:$C,"<"&B21+1,'📞 Call Tracker'!$D:$D,"YES")) -> 23 | E21: =IF(B21="","",COUNTIFS('📞 Call Tracker'!$C:$C,">="&B21,'📞 Call Tracker'!$C:$C,"<"&B21+1,'📞 Call Tracker'!$D:$D,"NO")) -> 18 | F21: =IF(B21="","",COUNTIFS('📞 Call Tracker'!$C:$C,">="&B21,'📞 Call Tracker'!$C:$C,"<"&B21+1,'📞 Call Tracker'!$B:$B,"Michelle")) -> 10 | G21: =IF(B21="","",COUNTIFS('📞 Call Tracker'!$C:$C,">="&B21,'📞 Call Tracker'!$C:$C,"<"&B21+1,'📞 Call Tracker'!$B:$B,"Joaquin")) -> 31
B22: 46053 | C22: =IF(B22="","",COUNTIFS('📞 Call Tracker'!$C:$C,">="&B22,'📞 Call Tracker'!$C:$C,"<"&B22+1)) -> 38 | D22: =IF(B22="","",COUNTIFS('📞 Call Tracker'!$C:$C,">="&B22,'📞 Call Tracker'!$C:$C,"<"&B22+1,'📞 Call Tracker'!$D:$D,"YES")) -> 22 | E22: =IF(B22="","",COUNTIFS('📞 Call Tracker'!$C:$C,">="&B22,'📞 Call Tracker'!$C:$C,"<"&B22+1,'📞 Call Tracker'!$D:$D,"NO")) -> 16 | F22: =IF(B22="","",COUNTIFS('📞 Call Tracker'!$C:$C,">="&B22,'📞 Call Tracker'!$C:$C,"<"&B22+1,'📞 Call Tracker'!$B:$B,"Michelle")) -> 10 | G22: =IF(B22="","",COUNTIFS('📞 Call Tracker'!$C:$C,">="&B22,'📞 Call Tracker'!$C:$C,"<"&B22+1,'📞 Call Tracker'!$B:$B,"Joaquin")) -> 28
B23: 46060 | C23: =IF(B23="","",COUNTIFS('📞 Call Tracker'!$C:$C,">="&B23,'📞 Call Tracker'!$C:$C,"<"&B23+1)) -> 38 | D23: =IF(B23="","",COUNTIFS('📞 Call Tracker'!$C:$C,">="&B23,'📞 Call Tracker'!$C:$C,"<"&B23+1,'📞 Call Tracker'!$D:$D,"YES")) -> 23 | E23: =IF(B23="","",COUNTIFS('📞 Call Tracker'!$C:$C,">="&B23,'📞 Call Tracker'!$C:$C,"<"&B23+1,'📞 Call Tracker'!$D:$D,"NO")) -> 14 | F23: =IF(B23="","",COUNTIFS('📞 Call Tracker'!$C:$C,">="&B23,'📞 Call Tracker'!$C:$C,"<"&B23+1,'📞 Call Tracker'!$B:$B,"Michelle")) -> 12 | G23: =IF(B23="","",COUNTIFS('📞 Call Tracker'!$C:$C,">="&B23,'📞 Call Tracker'!$C:$C,"<"&B23+1,'📞 Call Tracker'!$B:$B,"Joaquin")) -> 26
B24: 46067 | C24: =IF(B24="","",COUNTIFS('📞 Call Tracker'!$C:$C,">="&B24,'📞 Call Tracker'!$C:$C,"<"&B24+1)) -> 46 | D24: =IF(B24="","",COUNTIFS('📞 Call Tracker'!$C:$C,">="&B24,'📞 Call Tracker'!$C:$C,"<"&B24+1,'📞 Call Tracker'!$D:$D,"YES")) -> 28 | E24: =IF(B24="","",COUNTIFS('📞 Call Tracker'!$C:$C,">="&B24,'📞 Call Tracker'!$C:$C,"<"&B24+1,'📞 Call Tracker'!$D:$D,"NO")) -> 18 | F24: =IF(B24="","",COUNTIFS('📞 Call Tracker'!$C:$C,">="&B24,'📞 Call Tracker'!$C:$C,"<"&B24+1,'📞 Call Tracker'!$B:$B,"Michelle")) -> 22 | G24: =IF(B24="","",COUNTIFS('📞 Call Tracker'!$C:$C,">="&B24,'📞 Call Tracker'!$C:$C,"<"&B24+1,'📞 Call Tracker'!$B:$B,"Joaquin")) -> 24
B25: 46074 | C25: =IF(B25="","",COUNTIFS('📞 Call Tracker'!$C:$C,">="&B25,'📞 Call Tracker'!$C:$C,"<"&B25+1)) -> 42 | D25: =IF(B25="","",COUNTIFS('📞 Call Tracker'!$C:$C,">="&B25,'📞 Call Tracker'!$C:$C,"<"&B25+1,'📞 Call Tracker'!$D:$D,"YES")) -> 28 | E25: =IF(B25="","",COUNTIFS('📞 Call Tracker'!$C:$C,">="&B25,'📞 Call Tracker'!$C:$C,"<"&B25+1,'📞 Call Tracker'!$D:$D,"NO")) -> 14 | F25: =IF(B25="","",COUNTIFS('📞 Call Tracker'!$C:$C,">="&B25,'📞 Call Tracker'!$C:$C,"<"&B25+1,'📞 Call Tracker'!$B:$B,"Michelle")) -> 16 | G25: =IF(B25="","",COUNTIFS('📞 Call Tracker'!$C:$C,">="&B25,'📞 Call Tracker'!$C:$C,"<"&B25+1,'📞 Call Tracker'!$B:$B,"Joaquin")) -> 26
B26: 46081 | C26: =IF(B26="","",COUNTIFS('📞 Call Tracker'!$C:$C,">="&B26,'📞 Call Tracker'!$C:$C,"<"&B26+1)) -> 26 | E26: =IF(B26="","",COUNTIFS('📞 Call Tracker'!$C:$C,">="&B26,'📞 Call Tracker'!$C:$C,"<"&B26+1,'📞 Call Tracker'!$D:$D,"NO")) -> 15 | F26: =IF(B26="","",COUNTIFS('📞 Call Tracker'!$C:$C,">="&B26,'📞 Call Tracker'!$C:$C,"<"&B26+1,'📞 Call Tracker'!$B:$B,"Michelle")) -> 1 | G26: =IF(B26="","",COUNTIFS('📞 Call Tracker'!$C:$C,">="&B26,'📞 Call Tracker'!$C:$C,"<"&B26+1,'📞 Call Tracker'!$B:$B,"Joaquin")) -> 25
C27: =IF(B27="","",COUNTIFS('📞 Call Tracker'!$C:$C,">="&B27,'📞 Call Tracker'!$C:$C,"<"&B27+1)) | D27: =IF(B27="","",COUNTIFS('📞 Call Tracker'!$C:$C,">="&B27,'📞 Call Tracker'!$C:$C,"<"&B27+1,'📞 Call Tracker'!$D:$D,"YES")) | E27: =IF(B27="","",COUNTIFS('📞 Call Tracker'!$C:$C,">="&B27,'📞 Call Tracker'!$C:$C,"<"&B27+1,'📞 Call Tracker'!$D:$D,"NO")) | F27: =IF(B27="","",COUNTIFS('📞 Call Tracker'!$C:$C,">="&B27,'📞 Call Tracker'!$C:$C,"<"&B27+1,'📞 Call Tracker'!$B:$B,"Michelle")) | G27: =IF(B27="","",COUNTIFS('📞 Call Tracker'!$C:$C,">="&B27,'📞 Call Tracker'!$C:$C,"<"&B27+1,'📞 Call Tracker'!$B:$B,"Joaquin"))
B30: ASSOCIATE PERFORMANCE | F30: CALL OUTCOMES
B31: Associate | C31: Calls | D31: Contacts | F31: Outcome | G31: Count
B32: Michelle | C32: =COUNTIF('📞 Call Tracker'!B2:B2000,"Michelle") -> 103 | D32: =COUNTIFS('📞 Call Tracker'!B2:B2000,"Michelle",'📞 Call Tracker'!D2:D2000,"NO") -> 36 | F32: General Education | G32: =COUNTIF('📞 Call Tracker'!E2:E2000,"General Education") -> 75
B33: Joaquin | C33: =COUNTIF('📞 Call Tracker'!B2:B2000,"Joaquin") -> 296 | D33: =COUNTIFS('📞 Call Tracker'!B2:B2000,"Joaquin",'📞 Call Tracker'!D2:D2000,"NO") -> 97 | F33: Rate Change | G33: =COUNTIF('📞 Call Tracker'!E2:E2000,"Rate Change") -> 10
B34: Total | C34: =SUM(C32:C33) -> 399 | D34: =SUM(D32:D33) -> 133 | F34: Updated/New PA | G34: =COUNTIF('📞 Call Tracker'!E2:E2000,"Updated/New PA") -> 1
F35: Utility Assistance | G35: =COUNTIF('📞 Call Tracker'!E2:E2000,"Utility Assistance") -> 3
F36: E3/E4 | G36: =COUNTIF('📞 Call Tracker'!E2:E2000,"E3/E4") -> 7
F37: Other | G37: =COUNTIF('📞 Call Tracker'!E2:E2000,"Other (fill in)") -> 9
F38: VM - No Answer | G38: =COUNTIF('📞 Call Tracker'!D2:D2000,"YES") -> 244
B40: ="Last updated: "&TEXT(TODAY(),"mmmm d, yyyy") -> Last updated: March 4, 2026
B41: =_xlfn.LET(_xlpm.trackerTotal,COUNTA('📞 Call Tracker'!A2:A2000),"✅ "&_xlpm.trackerTotal&" customers in tracker ("&COUNTA('📞 Call Tracker'!B2:B2000)&" called, "&_xlpm.trackerTotal-COUNTA('📞 Call Tracker'!B2:B2000)&" remaining)") -> ✅ 1100 customers in tracker (399 called, 701 remaining)

Sheet Docketed Comments
A1: Date | B1: Last Name | C1: First Name | D1: City | E1: Zip code | F1: Issue / Complaint | G1: Docketed Consumer Comments | H1: Account # | I1: Rate Plan | J1: E3? | K1: MCP? | L1: Cust on MEP | M1: PA? | N1: Payoff Balance | O1: Team Reviewed | P1: Response Y(date)/N | Q1: Last date of Account review | R1: Notes | S1: ACC Inquiry Sent to CA | T1: APS CA Referral | U1: Comments | V1: Include_Row
A2: 45796 | B2: Abidali | C2: Sanar | D2: Glendale | E2: 85308 | F2: Opposed | G2: https://images.edocket.azcc.gov/docketpdf/E000044112.pdf | H2: Unable to Locate Acct | V2: =IF( OR( ISNUMBER(SEARCH("unable to locate acct", tblDocketedComments[[#This Row],[Docketed Consumer Comments]])), ISNUMBER(SEARCH("unknown", tblDocketedComments[[#This Row],[Docketed Consumer Comments]])), ISNUMBER(SEARCH("inactive", tblDocketedComments[[#This Row],[Docketed Consumer Comments]])) ), 0, 1 ) -> 1
A3: 45797 | B3: Paulus | C3: Carl | D3: Unknown | E3: Unknown | F3: Opposed | G3: https://images.edocket.azcc.gov/docketpdf/E000044128.pdf | H3: Unable to Locate Acct | V3: =IF( OR( ISNUMBER(SEARCH("unable to locate acct", tblDocketedComments[[#This Row],[Docketed Consumer Comments]])), ISNUMBER(SEARCH("unknown", tblDocketedComments[[#This Row],[Docketed Consumer Comments]])), ISNUMBER(SEARCH("inactive", tblDocketedComments[[#This Row],[Docketed Consumer Comments]])) ), 0, 1 ) -> 1
A4: 45797 | B4: Wall | C4: Rae | D4: Glendale | E4: Unknown | F4: Opposed | G4: https://images.edocket.azcc.gov/docketpdf/E000044126.pdf | H4: 5494061000 | I4: R3-47 | J4: No | K4: No | L4: Yes | M4: No | N4: No | O4: Yes | P4: N | Q4: 45589 | U4: Also filed 6/10, 6/12, 6/16 | V4: =IF( OR( ISNUMBER(SEARCH("unable to locate acct", tblDocketedComments[[#This Row],[Docketed Consumer Comments]])), ISNUMBER(SEARCH("unknown", tblDocketedComments[[#This Row],[Docketed Consumer Comments]])), ISNUMBER(SEARCH("inactive", tblDocketedComments[[#This Row],[Docketed Consumer Comments]])) ), 0, 1 ) -> 1
A5: 45798 | B5: Gwiazda | C5: Patricia | D5: Youngtown | E5: 85363 | F5: Opposed | G5: https://images.edocket.azcc.gov/docketpdf/E000044147.pdf | H5: 2074850000 | I5: RCPw/RTOUE47 | J5: No | K5: No | L5: No - MEP is R3-47 ($65.13) | M5: No | N5: No | O5: Yes | P5: N | Q5: 45589 | R5: MEP Annual Savings - $67.68 - Didn't Contact | V5: =IF( OR( ISNUMBER(SEARCH("unable to locate acct", tblDocketedComments[[#This Row],[Docketed Consumer Comments]])), ISNUMBER(SEARCH("unknown", tblDocketedComments[[#This Row],[Docketed Consumer Comments]])), ISNUMBER(SEARCH("inactive", tblDocketedComments[[#This Row],[Docketed Consumer Comments]])) ), 0, 1 ) -> 1
A6: 45798 | B6: Phillips | C6: Crystal | D6: Young | E6: 85554 | F6: Opposed | G6: https://images.edocket.azcc.gov/docketpdf/E000044147.pdf | H6: 4823746138 | I6: R3-47 | J6: No | K6: No | L6: Yes | M6: No | N6: No | O6: Yes | P6: N | Q6: 45589 | V6: =IF( OR( ISNUMBER(SEARCH("unable to locate acct", tblDocketedComments[[#This Row],[Docketed Consumer Comments]])), ISNUMBER(SEARCH("unknown", tblDocketedComments[[#This Row],[Docketed Consumer Comments]])), ISNUMBER(SEARCH("inactive", tblDocketedComments[[#This Row],[Docketed Consumer Comments]])) ), 0, 1 ) -> 1
A7: 45799 | B7: Beame | C7: Sndney | D7: Unknown | E7: Unknown | F7: Opposed/Senior/fixed income | G7: https://images.edocket.azcc.gov/docketpdf/E000044169.pdf | H7: 8991140195 | I7: R-BASICL | J7: No | K7: No | L7: No - MEP R3-47 ($192.78) | M7: No | N7: No | O7: Yes | P7: 45964 | Q7: 45954 | R7: 11/03 - Customer agreed to change to their MEP | U7: Estimated savings $225.94/12 = $18.82 potential monthly savings on MEP | V7: =IF( OR( ISNUMBER(SEARCH("unable to locate acct", tblDocketedComments[[#This Row],[Docketed Consumer Comments]])), ISNUMBER(SEARCH("unknown", tblDocketedComments[[#This Row],[Docketed Consumer Comments]])), ISNUMBER(SEARCH("inactive", tblDocketedComments[[#This Row],[Docketed Consumer Comments]])) ), 0, 1 ) -> 1
A8: 45800 | B8: Scoggins | C8: Troy | D8: Phoenix | E8: 85009 | F8: Opposed | G8: https://images.edocket.azcc.gov/docketpdf/E000044282.pdf | H8: Unknown | U8: Unable to locate account with name provided | V8: =IF( OR( ISNUMBER(SEARCH("unable to locate acct", tblDocketedComments[[#This Row],[Docketed Consumer Comments]])), ISNUMBER(SEARCH("unknown", tblDocketedComments[[#This Row],[Docketed Consumer Comments]])), ISNUMBER(SEARCH("inactive", tblDocketedComments[[#This Row],[Docketed Consumer Comments]])) ), 0, 1 ) -> 1
A9: 45804 | B9: Nuccio | C9: Tina | D9: Cave Creek | E9: 85331 | F9: Opposed | G9: https://images.edocket.azcc.gov/docketpdf/E000044298.pdf | H9: 5900820000 | I9: R3-47 | J9: No | K9: No | L9: Yes | M9: No | N9: No | O9: Yes | P9: N | Q9: 45954 | V9: =IF( OR( ISNUMBER(SEARCH("unable to locate acct", tblDocketedComments[[#This Row],[Docketed Consumer Comments]])), ISNUMBER(SEARCH("unknown", tblDocketedComments[[#This Row],[Docketed Consumer Comments]])), ISNUMBER(SEARCH("inactive", tblDocketedComments[[#This Row],[Docketed Consumer Comments]])) ), 0, 1 ) -> 1
A10: 45805 | B10: Henkel | C10: Dean | D10: Unknown | E10: Unknown | F10: Opposed | G10: https://images.edocket.azcc.gov/docketpdf/E000044312.pdf | H10: 1569851000 | I10: R-XS | J10: No | K10: No | L10: Yes | M10: No | N10: No | O10: Yes | P10: N | Q10: 45954 | V10: =IF( OR( ISNUMBER(SEARCH("unable to locate acct", tblDocketedComments[[#This Row],[Docketed Consumer Comments]])), ISNUMBER(SEARCH("unknown", tblDocketedComments[[#This Row],[Docketed Consumer Comments]])), ISNUMBER(SEARCH("inactive", tblDocketedComments[[#This Row],[Docketed Consumer Comments]])) ), 0, 1 ) -> 1
A11: 45812 | B11: Palmer | C11: William | D11: Unknown | E11: Unknown | F11: Opposed | G11: https://images.edocket.azcc.gov/docketpdf/E000044514.pdf | H11: Unable to Locate Acct | U11: Not able to locate specific account | V11: =IF( OR( ISNUMBER(SEARCH("unable to locate acct", tblDocketedComments[[#This Row],[Docketed Consumer Comments]])), ISNUMBER(SEARCH("unknown", tblDocketedComments[[#This Row],[Docketed Consumer Comments]])), ISNUMBER(SEARCH("inactive", tblDocketedComments[[#This Row],[Docketed Consumer Comments]])) ), 0, 1 ) -> 1
A12: 45812 | B12: Paulsen | C12: Jodi | D12: Unknown | E12: Unknown | F12: Opposed | G12: https://images.edocket.azcc.gov/docketpdf/E000044514.pdf | H12: 7938430000 | I12: EPR-6w/ET-1 | J12: No | K12: No | L12: Not able to Compare | M12: No | N12: No | O12: Yes | P12: N | Q12: 45957 | V12: =IF( OR( ISNUMBER(SEARCH("unable to locate acct", tblDocketedComments[[#This Row],[Docketed Consumer Comments]])), ISNUMBER(SEARCH("unknown", tblDocketedComments[[#This Row],[Docketed Consumer Comments]])), ISNUMBER(SEARCH("inactive", tblDocketedComments[[#This Row],[Docketed Consumer Comments]])) ), 0, 1 ) -> 1
A13: 45813 | B13: Berto | C13: Kim & Dave | D13: Chino Valley | E13: Unknown | F13: Opposed | G13: https://images.edocket.azcc.gov/docketpdf/E000044536.pdf | H13: 2009184288 | I13: RCPw/RTOUE47 | J13: No | K13: No | L13: Yes | M13: No | N13: No | O13: Yes | P13: N | Q13: 45957 | V13: =IF( OR( ISNUMBER(SEARCH("unable to locate acct", tblDocketedComments[[#This Row],[Docketed Consumer Comments]])), ISNUMBER(SEARCH("unknown", tblDocketedComments[[#This Row],[Docketed Consumer Comments]])), ISNUMBER(SEARCH("inactive", tblDocketedComments[[#This Row],[Docketed Consumer Comments]])) ), 0, 1 ) -> 1
A14: 45813 | B14: Misamore | C14: Bruce | D14: Sedona | E14: 86336 | F14: Opposed | G14: https://images.edocket.azcc.gov/docketpdf/E000044536.pdf | H14: Inactive Acct | J14: No | V14: =IF( OR( ISNUMBER(SEARCH("unable to locate acct", tblDocketedComments[[#This Row],[Docketed Consumer Comments]])), ISNUMBER(SEARCH("unknown", tblDocketedComments[[#This Row],[Docketed Consumer Comments]])), ISNUMBER(SEARCH("inactive", tblDocketedComments[[#This Row],[Docketed Consumer Comments]])) ), 0, 1 ) -> 1
A15: 45814 | B15: Shroyer | C15: Mary Lynne | D15: Sun City | E15: 85351 | F15: Opposed | G15: https://images.edocket.azcc.gov/docketpdf/E000044648.pdf | H15: 1163301000 | I15: R-XS | J15: No | K15: No | L15: Yes | M15: No | N15: No | O15: Yes | P15: N | Q15: 45957 | V15: =IF( OR( ISNUMBER(SEARCH("unable to locate acct", tblDocketedComments[[#This Row],[Docketed Consumer Comments]])), ISNUMBER(SEARCH("unknown", tblDocketedComments[[#This Row],[Docketed Consumer Comments]])), ISNUMBER(SEARCH("inactive", tblDocketedComments[[#This Row],[Docketed Consumer Comments]])) ), 0, 1 ) -> 1
A16: 45821 | B16: Driscoll | C16: David & Donna | D16: Unknown | E16: Unknown | F16: Opposed | G16: https://images.edocket.azcc.gov/docketpdf/E000044766.pdf | H16: 6242500593 | I16: RCPw/RTOUE47 | J16: No | K16: No | L16: No - MEP R3-47($151.35) | M16: No | N16: No | O16: Yes | P16: N | Q16: 45957 | R16: Prior ACC Complaint customer - Solar customer does not want to be on demand rate. | V16: =IF( OR( ISNUMBER(SEARCH("unable to locate acct", tblDocketedComments[[#This Row],[Docketed Consumer Comments]])), ISNUMBER(SEARCH("unknown", tblDocketedComments[[#This Row],[Docketed Consumer Comments]])), ISNUMBER(SEARCH("inactive", tblDocketedComments[[#This Row],[Docketed Consumer Comments]])) ), 0, 1 ) -> 1
A17: 45824 | B17: Hix | C17: Debbie | D17: Unknown | E17: Unknown | F17: Opposed | G17: https://images.edocket.azcc.gov/docketpdf/E000044775.pdf https://images.edocket.azcc.gov/docketpdf/E000044791.pdf | H17: Unable to Locate Acct | U17: Filed 2x on 6/16 (Thompson and Myers), Not able to locate specific account | V17: =IF( OR( ISNUMBER(SEARCH("unable to locate acct", tblDocketedComments[[#This Row],[Docketed Consumer Comments]])), ISNUMBER(SEARCH("unknown", tblDocketedComments[[#This Row],[Docketed Consumer Comments]])), ISNUMBER(SEARCH("inactive", tblDocketedComments[[#This Row],[Docketed Consumer Comments]])) ), 0, 1 ) -> 1
A18: 45824 | B18: Montana | C18: Casitas | D18: Unknown | E18: Unknown | F18: Opposed | G18: https://images.edocket.azcc.gov/docketpdf/E000044777.pdf | H18: Unable to Locate Acct | V18: =IF( OR( ISNUMBER(SEARCH("unable to locate acct", tblDocketedComments[[#This Row],[Docketed Consumer Comments]])), ISNUMBER(SEARCH("unknown", tblDocketedComments[[#This Row],[Docketed Consumer Comments]])), ISNUMBER(SEARCH("inactive", tblDocketedComments[[#This Row],[Docketed Consumer Comments]])) ), 0, 1 ) -> 1
A19: 45824 | B19: Paulus | C19: Carl | D19: Unknown | E19: Unknown | F19: Opposed | G19: https://images.edocket.azcc.gov/docketpdf/E000044776.pdf | H19: Unable to Locate Acct | U19: Filed on 5/18 and 6/16 | V19: =IF( OR( ISNUMBER(SEARCH("unable to locate acct", tblDocketedComments[[#This Row],[Docketed Consumer Comments]])), ISNUMBER(SEARCH("unknown", tblDocketedComments[[#This Row],[Docketed Consumer Comments]])), ISNUMBER(SEARCH("inactive", tblDocketedComments[[#This Row],[Docketed Consumer Comments]])) ), 0, 1 ) -> 1
A20: 45825 | B20: Carpio | C20: Tania | D20: Surprise | E20: 85379 | F20: Opposed | G20: https://images.edocket.azcc.gov/docketpdf/E000044799.pdf | H20: Unable to Locate Acct | V20: =IF( OR( ISNUMBER(SEARCH("unable to locate acct", tblDocketedComments[[#This Row],[Docketed Consumer Comments]])), ISNUMBER(SEARCH("unknown", tblDocketedComments[[#This Row],[Docketed Consumer Comments]])), ISNUMBER(SEARCH("inactive", tblDocketedComments[[#This Row],[Docketed Consumer Comments]])) ), 0, 1 ) -> 1
A21: 45825 | B21: Mansour | C21: Joe | D21: Surprise | E21: 85387 | F21: Opposed | G21: https://images.edocket.azcc.gov/docketpdf/E000044799.pdf | H21: Unable to Locate Acct | V21: =IF( OR( ISNUMBER(SEARCH("unable to locate acct", tblDocketedComments[[#This Row],[Docketed Consumer Comments]])), ISNUMBER(SEARCH("unknown", tblDocketedComments[[#This Row],[Docketed Consumer Comments]])), ISNUMBER(SEARCH("inactive", tblDocketedComments[[#This Row],[Docketed Consumer Comments]])) ), 0, 1 ) -> 1
A22: 45825 | B22: Neal | C22: Michelle | D22: Glendale | E22: 85308 | F22: Opposed | G22: https://images.edocket.azcc.gov/docketpdf/E000044799.pdf | H22: 1565756559 | I22: R3-47 | J22: No | K22: No | L22: Yes | M22: No | N22: No | O22: Yes | P22: N | Q22: 45957 | V22: =IF( OR( ISNUMBER(SEARCH("unable to locate acct", tblDocketedComments[[#This Row],[Docketed Consumer Comments]])), ISNUMBER(SEARCH("unknown", tblDocketedComments[[#This Row],[Docketed Consumer Comments]])), ISNUMBER(SEARCH("inactive", tblDocketedComments[[#This Row],[Docketed Consumer Comments]])) ), 0, 1 ) -> 1
A23: 45826 | B23: Couillard | C23: Andre | D23: Phoenix | E23: 85027 | F23: Opposed | G23: https://images.edocket.azcc.gov/docketpdf/E000044842.pdf | H23: Unable to Locate Acct | U23: Filed 2x on 6/18 | V23: =IF( OR( ISNUMBER(SEARCH("unable to locate acct", tblDocketedComments[[#This Row],[Docketed Consumer Comments]])), ISNUMBER(SEARCH("unknown", tblDocketedComments[[#This Row],[Docketed Consumer Comments]])), ISNUMBER(SEARCH("inactive", tblDocketedComments[[#This Row],[Docketed Consumer Comments]])) ), 0, 1 ) -> 1
A24: 45826 | B24: Witte | C24: Jessica | D24: Scottsdale | E24: 85254 | F24: Opposed | G24: https://images.edocket.azcc.gov/docketpdf/E000044842.pdf | H24: 7413433376 | I24: R-BASIC | J24: No | K24: No | L24: Yes | M24: No | N24: No | O24: Yes | P24: N | Q24: 45957 | V24: =IF( OR( ISNUMBER(SEARCH("unable to locate acct", tblDocketedComments[[#This Row],[Docketed Consumer Comments]])), ISNUMBER(SEARCH("unknown", tblDocketedComments[[#This Row],[Docketed Consumer Comments]])), ISNUMBER(SEARCH("inactive", tblDocketedComments[[#This Row],[Docketed Consumer Comments]])) ), 0, 1 ) -> 1
A25: 45826 | B25: Figueroa | C25: Enrique | D25: Gilbert | E25: 85233 | F25: Opposed | G25: https://images.edocket.azcc.gov/docketpdf/E000044842.pdf | H25: 6601188228 | I25: R3-47 | J25: No | K25: No | L25: Yes | M25: No | N25: No | O25: Yes | P25: N | Q25: 45957 | V25: =IF( OR( ISNUMBER(SEARCH("unable to locate acct", tblDocketedComments[[#This Row],[Docketed Consumer Comments]])), ISNUMBER(SEARCH("unknown", tblDocketedComments[[#This Row],[Docketed Consumer Comments]])), ISNUMBER(SEARCH("inactive", tblDocketedComments[[#This Row],[Docketed Consumer Comments]])) ), 0, 1 ) -> 1
A26: 45826 | B26: Wheatley | C26: Heather | D26: Surprise | E26: 85388 | F26: Opposed | G26: https://images.edocket.azcc.gov/docketpdf/E000044842.pdf | H26: 7397110970 | I26: R3-47 | J26: No | K26: No | L26: Yes | M26: No | N26: No | O26: Yes | P26: N | Q26: 45957 | V26: =IF( OR( ISNUMBER(SEARCH("unable to locate acct", tblDocketedComments[[#This Row],[Docketed Consumer Comments]])), ISNUMBER(SEARCH("unknown", tblDocketedComments[[#This Row],[Docketed Consumer Comments]])), ISNUMBER(SEARCH("inactive", tblDocketedComments[[#This Row],[Docketed Consumer Comments]])) ), 0, 1 ) -> 1
A27: 45826 | B27: Millbranth | C27: Mark | D27: Scottsdale | E27: 85266 | F27: Opposed | G27: https://images.edocket.azcc.gov/docketpdf/E000044842.pdf | H27: 5288831000 | I27: R3-47 | J27: No | K27: No | L27: Yes | M27: No | N27: No | O27: Yes | P27: N | Q27: 45957 | V27: =IF( OR( ISNUMBER(SEARCH("unable to locate acct", tblDocketedComments[[#This Row],[Docketed Consumer Comments]])), ISNUMBER(SEARCH("unknown", tblDocketedComments[[#This Row],[Docketed Consumer Comments]])), ISNUMBER(SEARCH("inactive", tblDocketedComments[[#This Row],[Docketed Consumer Comments]])) ), 0, 1 ) -> 1
A28: 45826 | B28: Wilson | C28: John | D28: Carefree | E28: Unknown | F28: Opposed | G28: https://images.edocket.azcc.gov/docketpdf/E000044846.pdf | H28: Unable to Locate Acct | U28: Not able to locate specific account | V28: =IF( OR( ISNUMBER(SEARCH("unable to locate acct", tblDocketedComments[[#This Row],[Docketed Consumer Comments]])), ISNUMBER(SEARCH("unknown", tblDocketedComments[[#This Row],[Docketed Consumer Comments]])), ISNUMBER(SEARCH("inactive", tblDocketedComments[[#This Row],[Docketed Consumer Comments]])) ), 0, 1 ) -> 1
A29: 45826 | B29: Geyer | C29: Jared | D29: Scottsdale | E29: 85254 | F29: Opposed | G29: https://images.edocket.azcc.gov/docketpdf/E000044846.pdf | H29: 7528633936 | I29: R-BASICL | J29: No | K29: No | L29: No MEP R3-47 ($36.88) | M29: No | N29: No | O29: Yes | P29: N | Q29: 45957 | U29: Estimated savings $37.01/12 = $3.08 potential monthly savings on MEP | V29: =IF( OR( ISNUMBER(SEARCH("unable to locate acct", tblDocketedComments[[#This Row],[Docketed Consumer Comments]])), ISNUMBER(SEARCH("unknown", tblDocketedComments[[#This Row],[Docketed Consumer Comments]])), ISNUMBER(SEARCH("inactive", tblDocketedComments[[#This Row],[Docketed Consumer Comments]])) ), 0, 1 ) -> 1
A30: 45826 | B30: Snyder | C30: Steven | D30: Phoenix | E30: 85029 | F30: Opposed | G30: https://images.edocket.azcc.gov/docketpdf/E000044846.pdf | H30: 4262494925 | I30: R3-47 | J30: No | K30: No | L30: No MEP R-XS ($110.29) | M30: No | N30: No | O30: Yes | P30: 45964 | Q30: 45957 | R30: 11/03 - LM | U30: Estimated savings $43.66/12 = $3.63 potential monthly savings on MEP | V30: =IF( OR( ISNUMBER(SEARCH("unable to locate acct", tblDocketedComments[[#This Row],[Docketed Consumer Comments]])), ISNUMBER(SEARCH("unknown", tblDocketedComments[[#This Row],[Docketed Consumer Comments]])), ISNUMBER(SEARCH("inactive", tblDocketedComments[[#This Row],[Docketed Consumer Comments]])) ), 0, 1 ) -> 1
A31: 45826 | B31: Buehler | C31: Mark | D31: Unknown | E31: Unknown | F31: Opposed | G31: https://images.edocket.azcc.gov/docketpdf/E000044840.pdf | H31: Unable to Locate Acct | U31: Not able to locate specific account | V31: =IF( OR( ISNUMBER(SEARCH("unable to locate acct", tblDocketedComments[[#This Row],[Docketed Consumer Comments]])), ISNUMBER(SEARCH("unknown", tblDocketedComments[[#This Row],[Docketed Consumer Comments]])), ISNUMBER(SEARCH("inactive", tblDocketedComments[[#This Row],[Docketed Consumer Comments]])) ), 0, 1 ) -> 1
A32: 45826 | B32: Kaplan | C32: Wayne | D32: Unknown | E32: Unknown | F32: Opposed | G32: https://images.edocket.azcc.gov/docketpdf/E000044840.pdf | H32: 4273250000 | I32: R-XS | J32: No | K32: No | L32: Yes | M32: No | N32: No | O32: Yes | P32: N | Q32: 45957 | V32: =IF( OR( ISNUMBER(SEARCH("unable to locate acct", tblDocketedComments[[#This Row],[Docketed Consumer Comments]])), ISNUMBER(SEARCH("unknown", tblDocketedComments[[#This Row],[Docketed Consumer Comments]])), ISNUMBER(SEARCH("inactive", tblDocketedComments[[#This Row],[Docketed Consumer Comments]])) ), 0, 1 ) -> 1
A33: 45826 | B33: Delgado | C33: Amber | D33: Unknown | E33: Unknown | F33: Opposed | G33: https://images.edocket.azcc.gov/docketpdf/E000044840.pdf | H33: 8714231000 | I33: R3-47 | J33: No | K33: No | L33: Yes | M33: No | N33: No | O33: Yes | P33: N | Q33: 45957 | R33: Changed rate to MEP on 10/6 | U33: Estimated savings $68.27/12 - $5.69 potential monthly savings on MEP | V33: =IF( OR( ISNUMBER(SEARCH("unable to locate acct", tblDocketedComments[[#This Row],[Docketed Consumer Comments]])), ISNUMBER(SEARCH("unknown", tblDocketedComments[[#This Row],[Docketed Consumer Comments]])), ISNUMBER(SEARCH("inactive", tblDocketedComments[[#This Row],[Docketed Consumer Comments]])) ), 0, 1 ) -> 1
A34: 45826 | B34: Reyes | C34: Michelle | D34: Glendale | E34: 85310 | F34: Opposed | G34: https://images.edocket.azcc.gov/docketpdf/E000044840.pdf | H34: Unable to Locate Acct | U34: Not able to locate specific account | V34: =IF( OR( ISNUMBER(SEARCH("unable to locate acct", tblDocketedComments[[#This Row],[Docketed Consumer Comments]])), ISNUMBER(SEARCH("unknown", tblDocketedComments[[#This Row],[Docketed Consumer Comments]])), ISNUMBER(SEARCH("inactive", tblDocketedComments[[#This Row],[Docketed Consumer Comments]])) ), 0, 1 ) -> 1
A35: 45826 | B35: Saporito | C35: Annette | D35: Cave Creek | E35: 85331 | F35: Opposed | G35: https://images.edocket.azcc.gov/docketpdf/E000044840.pdf | H35: 7980600000 | I35: RTOUE47 | J35: No | K35: No | L35: No R3-47 ($439.74) | M35: No | N35: No | O35: Yes | P35: 45964 | Q35: 45957 | R35: 11/03 - LM | U35: Estimated savings $433.16/12 = $36.09 potential monthly savings on MEP | V35: =IF( OR( ISNUMBER(SEARCH("unable to locate acct", tblDocketedComments[[#This Row],[Docketed Consumer Comments]])), ISNUMBER(SEARCH("unknown", tblDocketedComments[[#This Row],[Docketed Consumer Comments]])), ISNUMBER(SEARCH("inactive", tblDocketedComments[[#This Row],[Docketed Consumer Comments]])) ), 0, 1 ) -> 1
A36: 45827 | B36: Miller | C36: D | D36: Goodyear | E36: Unknown | F36: Opposed, thinks Budget billing is a scam | G36: https://images.edocket.azcc.gov/docketpdf/0000214768.pdf | H36: Unable to Locate Acct | U36: Not able to locate specific account | V36: =IF( OR( ISNUMBER(SEARCH("unable to locate acct", tblDocketedComments[[#This Row],[Docketed Consumer Comments]])), ISNUMBER(SEARCH("unknown", tblDocketedComments[[#This Row],[Docketed Consumer Comments]])), ISNUMBER(SEARCH("inactive", tblDocketedComments[[#This Row],[Docketed Consumer Comments]])) ), 0, 1 ) -> 1
A37: 45827 | B37: Gray | C37: Tim | D37: Buckeye | E37: Unknown | F37: Opposed | G37: https://images.edocket.azcc.gov/docketpdf/E000044863.pdf | H37: Unable to Locate Acct | U37: Not able to locate specific account | V37: =IF( OR( ISNUMBER(SEARCH("unable to locate acct", tblDocketedComments[[#This Row],[Docketed Consumer Comments]])), ISNUMBER(SEARCH("unknown", tblDocketedComments[[#This Row],[Docketed Consumer Comments]])), ISNUMBER(SEARCH("inactive", tblDocketedComments[[#This Row],[Docketed Consumer Comments]])) ), 0, 1 ) -> 1
A38: 45827 | B38: Garcia | C38: Amy | D38: Unknown | E38: Unknown | F38: Opposed | G38: https://images.edocket.azcc.gov/docketpdf/E000044863.pdf | H38: Unable to Locate Acct | U38: Not able to locate specific account | V38: =IF( OR( ISNUMBER(SEARCH("unable to locate acct", tblDocketedComments[[#This Row],[Docketed Consumer Comments]])), ISNUMBER(SEARCH("unknown", tblDocketedComments[[#This Row],[Docketed Consumer Comments]])), ISNUMBER(SEARCH("inactive", tblDocketedComments[[#This Row],[Docketed Consumer Comments]])) ), 0, 1 ) -> 1
A39: 45827 | B39: Merlino | C39: Teri | D39: Unknown | E39: Unknown | F39: Opposed | G39: https://images.edocket.azcc.gov/docketpdf/E000044863.pdf | H39: 3007031000 | I39: R3-47 | J39: No | K39: No | L39: Yes | M39: No | N39: No | O39: Yes | P39: N | Q39: 45957 | V39: =IF( OR( ISNUMBER(SEARCH("unable to locate acct", tblDocketedComments[[#This Row],[Docketed Consumer Comments]])), ISNUMBER(SEARCH("unknown", tblDocketedComments[[#This Row],[Docketed Consumer Comments]])), ISNUMBER(SEARCH("inactive", tblDocketedComments[[#This Row],[Docketed Consumer Comments]])) ), 0, 1 ) -> 1
A40: 45827 | B40: Escamilla | C40: Nephesh | D40: Phoenix | E40: Unknown | F40: Opposed | G40: https://images.edocket.azcc.gov/docketpdf/E000044866.pdf | H40: Unable to Locate Acct | V40: =IF( OR( ISNUMBER(SEARCH("unable to locate acct", tblDocketedComments[[#This Row],[Docketed Consumer Comments]])), ISNUMBER(SEARCH("unknown", tblDocketedComments[[#This Row],[Docketed Consumer Comments]])), ISNUMBER(SEARCH("inactive", tblDocketedComments[[#This Row],[Docketed Consumer Comments]])) ), 0, 1 ) -> 1
...

Sheet 📋 Build Guides
A1: ═══════════════════════════════════════════════
A2: POWER APPS BUILD GUIDE — APS Rate Case Call Tracker
A3: ═══════════════════════════════════════════════
A5: PREREQUISITES
A6: • This Excel file must be on SharePoint or OneDrive for Business
A7: • You need Power Apps access (included with M365 Business/Enterprise)
A8: • The file has an Excel Table called tblCallTracker on the Call Tracker sheet
A10: STEP 1: CREATE THE APP (5 min)
A11: 1. Go to make.powerapps.com
A12: 2. Click + Create → Start with data → Excel
A13: 3. Connect to your SharePoint site → navigate to this Excel file
A14: 4. Select tblCallTracker → Click Connect
... A145: Issue | Text | Customer complaint | Read-only

Sheet Call Queue
A1: Date Added | B1: Last Name | C1: First Name | D1: City | E1: Zip code | F1: Issue / Complaint | G1: 📄 Link | H1: Account # | I1: Rate Plan | J1: E3? | K1: MCP? | L1: MEP Status | M1: PA? | N1: Payoff Balance | O1: Team Reviewed | P1: Response Y(date)/N | Q1: Last date of Account review | R1: Notes | S1: ACC Inquiry Sent to CA | T1: APS CA Referral | U1: Comments | V1: MEP Status (Clean) | W1: ✏️ Associate | X1: ✏️ Date Called | Y1: ✏️ VM? | Z1: ✏️ Outcome | AA1: ✏️ Notes | AB1: Priority
A2: {=IFERROR(_xlfn._xlws.FILTER('Docketed Comments'!A2:A1949,('Docketed Comments'!H2:H1949<>"Unable to Locate Acct")*('Docketed Comments'!H2:H1949<>"")*('Docketed Comments'!H2:H1949<>0)*(_xlfn.XMATCH('Docketed Comments'!H2:H1949,'Docketed Comments'!H$2:H$1949)=_xlfn.SEQUENCE(1948))),"")} -> 45797 | B2: {=IFERROR(_xlfn._xlws.FILTER('Docketed Comments'!B2:B1949,('Docketed Comments'!H2:H1949<>"Unable to Locate Acct")*('Docketed Comments'!H2:H1949<>"")*('Docketed Comments'!H2:H1949<>0)*(_xlfn.XMATCH('Docketed Comments'!H2:H1949,'Docketed Comments'!H$2:H$1949)=_xlfn.SEQUENCE(1948))),"")} -> Wall | C2: {=IFERROR(_xlfn._xlws.FILTER('Docketed Comments'!C2:C1949,('Docketed Comments'!H2:H1949<>"Unable to Locate Acct")*('Docketed Comments'!H2:H1949<>"")*('Docketed Comments'!H2:H1949<>0)*(_xlfn.XMATCH('Docketed Comments'!H2:H1949,'Docketed Comments'!H$2:H$1949)=_xlfn.SEQUENCE(1948))),"")} -> Rae | D2: {=IFERROR(_xlfn._xlws.FILTER('Docketed Comments'!D2:D1949,('Docketed Comments'!H2:H1949<>"Unable to Locate Acct")*('Docketed Comments'!H2:H1949<>"")*('Docketed Comments'!H2:H1949<>0)*(_xlfn.XMATCH('Docketed Comments'!H2:H1949,'Docketed Comments'!H$2:H$1949)=_xlfn.SEQUENCE(1948))),"")} -> Glendale | E2: {=IFERROR(_xlfn._xlws.FILTER('Docketed Comments'!E2:E1949,('Docketed Comments'!H2:H1949<>"Unable to Locate Acct")*('Docketed Comments'!H2:H1949<>"")*('Docketed Comments'!H2:H1949<>0)*(_xlfn.XMATCH('Docketed Comments'!H2:H1949,'Docketed Comments'!H$2:H$1949)=_xlfn.SEQUENCE(1948))),"")} -> Unknown | F2: {=IFERROR(_xlfn._xlws.FILTER('Docketed Comments'!F2:F1949,('Docketed Comments'!H2:H1949<>"Unable to Locate Acct")*('Docketed Comments'!H2:H1949<>"")*('Docketed Comments'!H2:H1949<>0)*(_xlfn.XMATCH('Docketed Comments'!H2:H1949,'Docketed Comments'!H$2:H$1949)=_xlfn.SEQUENCE(1948))),"")} -> Opposed | G2: {=IFERROR(_xlfn._xlws.FILTER('Docketed Comments'!G2:G1949,('Docketed Comments'!H2:H1949<>"Unable to Locate Acct")*('Docketed Comments'!H2:H1949<>"")*('Docketed Comments'!H2:H1949<>0)*(_xlfn.XMATCH('Docketed Comments'!H2:H1949,'Docketed Comments'!H$2:H$1949)=_xlfn.SEQUENCE(1948))),"")} -> https://images.edocket.azcc.gov/docketpdf/E000044126.pdf | H2: 5494061000 | I2: {=IFERROR(_xlfn._xlws.FILTER('Docketed Comments'!I2:I1949,('Docketed Comments'!H2:H1949<>"Unable to Locate Acct")*('Docketed Comments'!H2:H1949<>"")*('Docketed Comments'!H2:H1949<>0)*(_xlfn.XMATCH('Docketed Comments'!H2:H1949,'Docketed Comments'!H$2:H$1949)=_xlfn.SEQUENCE(1948))),"")} -> R3-47 | J2: {=IFERROR(_xlfn._xlws.FILTER('Docketed Comments'!J2:J1949,('Docketed Comments'!H2:H1949<>"Unable to Locate Acct")*('Docketed Comments'!H2:H1949<>"")*('Docketed Comments'!H2:H1949<>0)*(_xlfn.XMATCH('Docketed Comments'!H2:H1949,'Docketed Comments'!H$2:H$1949)=_xlfn.SEQUENCE(1948))),"")} -> No | K2: {=IFERROR(_xlfn._xlws.FILTER('Docketed Comments'!K2:K1949,('Docketed Comments'!H2:H1949<>"Unable to Locate Acct")*('Docketed Comments'!H2:H1949<>"")*('Docketed Comments'!H2:H1949<>0)*(_xlfn.XMATCH('Docketed Comments'!H2:H1949,'Docketed Comments'!H$2:H$1949)=_xlfn.SEQUENCE(1948))),"")} -> No | L2: {=IFERROR(_xlfn._xlws.FILTER('Docketed Comments'!L2:L1949,('Docketed Comments'!H2:H1949<>"Unable to Locate Acct")*('Docketed Comments'!H2:H1949<>"")*('Docketed Comments'!H2:H1949<>0)*(_xlfn.XMATCH('Docketed Comments'!H2:H1949,'Docketed Comments'!H$2:H$1949)=_xlfn.SEQUENCE(1948))),"")} -> Yes | M2: {=IFERROR(_xlfn._xlws.FILTER('Docketed Comments'!M2:M1949,('Docketed Comments'!H2:H1949<>"Unable to Locate Acct")*('Docketed Comments'!H2:H1949<>"")*('Docketed Comments'!H2:H1949<>0)*(_xlfn.XMATCH('Docketed Comments'!H2:H1949,'Docketed Comments'!H$2:H$1949)=_xlfn.SEQUENCE(1948))),"")} -> No | N2: {=IFERROR(_xlfn._xlws.FILTER('Docketed Comments'!N2:N1949,('Docketed Comments'!H2:H1949<>"Unable to Locate Acct")*('Docketed Comments'!H2:H1949<>"")*('Docketed Comments'!H2:H1949<>0)*(_xlfn.XMATCH('Docketed Comments'!H2:H1949,'Docketed Comments'!H$2:H$1949)=_xlfn.SEQUENCE(1948))),"")} -> No | O2: {=IFERROR(_xlfn._xlws.FILTER('Docketed Comments'!O2:O1949,('Docketed Comments'!H2:H1949<>"Unable to Locate Acct")*('Docketed Comments'!H2:H1949<>"")*('Docketed Comments'!H2:H1949<>0)*(_xlfn.XMATCH('Docketed Comments'!H2:H1949,'Docketed Comments'!H$2:H$1949)=_xlfn.SEQUENCE(1948))),"")} -> Yes | P2: {=IFERROR(_xlfn._xlws.FILTER('Docketed Comments'!P2:P1949,('Docketed Comments'!H2:H1949<>"Unable to Locate Acct")*('Docketed Comments'!H2:H1949<>"")*('Docketed Comments'!H2:H1949<>0)*(_xlfn.XMATCH('Docketed Comments'!H2:H1949,'Docketed Comments'!H$2:H$1949)=_xlfn.SEQUENCE(1948))),"")} -> N | Q2: {=IFERROR(_xlfn._xlws.FILTER('Docketed Comments'!Q2:Q1949,('Docketed Comments'!H2:H1949<>"Unable to Locate Acct")*('Docketed Comments'!H2:H1949<>"")*('Docketed Comments'!H2:H1949<>0)*(_xlfn.XMATCH('Docketed Comments'!H2:H1949,'Docketed Comments'!H$2:H$1949)=_xlfn.SEQUENCE(1948))),"")} -> 45589 | R2: {=IFERROR(_xlfn._xlws.FILTER('Docketed Comments'!R2:R1949,('Docketed Comments'!H2:H1949<>"Unable to Locate Acct")*('Docketed Comments'!H2:H1949<>"")*('Docketed Comments'!H2:H1949<>0)*(_xlfn.XMATCH('Docketed Comments'!H2:H1949,'Docketed Comments'!H$2:H$1949)=_xlfn.SEQUENCE(1948))),"")} -> 0 | S2: {=IFERROR(_xlfn._xlws.FILTER('Docketed Comments'!S2:S1949,('Docketed Comments'!H2:H1949<>"Unable to Locate Acct")*('Docketed Comments'!H2:H1949<>"")*('Docketed Comments'!H2:H1949<>0)*(_xlfn.XMATCH('Docketed Comments'!H2:H1949,'Docketed Comments'!H$2:H$1949)=_xlfn.SEQUENCE(1948))),"")} -> 0 | T2: {=IFERROR(_xlfn._xlws.FILTER('Docketed Comments'!T2:T1949,('Docketed Comments'!H2:H1949<>"Unable to Locate Acct")*('Docketed Comments'!H2:H1949<>"")*('Docketed Comments'!H2:H1949<>0)*(_xlfn.XMATCH('Docketed Comments'!H2:H1949,'Docketed Comments'!H$2:H$1949)=_xlfn.SEQUENCE(1948))),"")} -> 0 | U2: {=IFERROR(_xlfn._xlws.FILTER('Docketed Comments'!U2:U1949,('Docketed Comments'!H2:H1949<>"Unable to Locate Acct")*('Docketed Comments'!H2:H1949<>"")*('Docketed Comments'!H2:H1949<>0)*(_xlfn.XMATCH('Docketed Comments'!H2:H1949,'Docketed Comments'!H$2:H$1949)=_xlfn.SEQUENCE(1948))),"")} -> Also filed 6/10, 6/12, 6/16 | V2: =IF(OR(LEFT(TRIM(L2),3)="Yes",TRIM(L2)="Y"),"✅ On Best Plan",IF(OR(L2="Frozen Rate",L2="Frozen Plan"),"❄ Frozen Rate",IF(OR(L2="Not able to Compare",L2="Info Not Avail",L2="NA",L2=""),"⚠ Unknown","❌ Not on Best Plan"))) -> ✅ On Best Plan | W2: =IFERROR(_xlfn.XLOOKUP(TEXT(H2,"0000000000"),'📞 Call Tracker'!A$2:A$2000,'📞 Call Tracker'!B$2:B$2000,""),"") -> Joaquin | X2: =IFERROR(_xlfn.XLOOKUP(TEXT(H2,"0000000000"),'📞 Call Tracker'!A$2:A$2000,'📞 Call Tracker'!C$2:C$2000,""),"") -> 45997 | Y2: =IFERROR(_xlfn.XLOOKUP(TEXT(H2,"0000000000"),'📞 Call Tracker'!A$2:A$2000,'📞 Call Tracker'!D$2:D$2000,""),"") -> YES | Z2: =IFERROR(_xlfn.XLOOKUP(TEXT(H2,"0000000000"),'📞 Call Tracker'!A$2:A$2000,'📞 Call Tracker'!E$2:E$2000,""),"") -> 0 | AA2: =IFERROR(_xlfn.XLOOKUP(TEXT(H2,"0000000000"),'📞 Call Tracker'!A$2:A$2000,'📞 Call Tracker'!F$2:F$2000,""),"") -> LEFT VOICE MAIL | AB2: =IF(OR(H2="",X2<>""),99,IF(AND(NOT(OR(LEFT(TRIM(L2),3)="Yes",TRIM(L2)="Y",L2="Frozen Rate",L2="Frozen Plan",L2="Not able to Compare",L2="Info Not Avail",L2="NA",L2="")),AND(N2<>"No",N2<>"")),1,IF(NOT(OR(LEFT(TRIM(L2),3)="Yes",TRIM(L2)="Y",L2="Frozen Rate",L2="Frozen Plan",L2="Not able to Compare",L2="Info Not Avail",L2="NA",L2="")),2,IF(AND(N2<>"No",N2<>""),3,4)))) -> 99
A3: 45798 | B3: Gwiazda | C3: Patricia | D3: Youngtown | E3: 85363 | F3: Opposed | G3: https://images.edocket.azcc.gov/docketpdf/E000044147.pdf | H3: 2074850000 | I3: RCPw/RTOUE47 | J3: No | K3: No | L3: No - MEP is R3-47 ($65.13) | M3: No | N3: No | O3: Yes | P3: N | Q3: 45589 | R3: MEP Annual Savings - $67.68 - Didn't Contact | S3: 0 | T3: 0 | U3: 0 | V3: =IF(OR(LEFT(TRIM(L3),3)="Yes",TRIM(L3)="Y"),"✅ On Best Plan",IF(OR(L3="Frozen Rate",L3="Frozen Plan"),"❄ Frozen Rate",IF(OR(L3="Not able to Compare",L3="Info Not Avail",L3="NA",L3=""),"⚠ Unknown","❌ Not on Best Plan"))) -> ❌ Not on Best Plan | W3: =IFERROR(_xlfn.XLOOKUP(TEXT(H3,"0000000000"),'📞 Call Tracker'!A$2:A$2000,'📞 Call Tracker'!B$2:B$2000,""),"") -> Joaquin | X3: =IFERROR(_xlfn.XLOOKUP(TEXT(H3,"0000000000"),'📞 Call Tracker'!A$2:A$2000,'📞 Call Tracker'!C$2:C$2000,""),"") -> 45997 | Y3: =IFERROR(_xlfn.XLOOKUP(TEXT(H3,"0000000000"),'📞 Call Tracker'!A$2:A$2000,'📞 Call Tracker'!D$2:D$2000,""),"") -> 0 | Z3: =IFERROR(_xlfn.XLOOKUP(TEXT(H3,"0000000000"),'📞 Call Tracker'!A$2:A$2000,'📞 Call Tracker'!E$2:E$2000,""),"") -> 0 | AA3: =IFERROR(_xlfn.XLOOKUP(TEXT(H3,"0000000000"),'📞 Call Tracker'!A$2:A$2000,'📞 Call Tracker'!F$2:F$2000,""),"") -> DID TALK PHILLIPS,CRYSTAL OFFER REVIEW ACCT | AB3: =IF(OR(H3="",X3<>""),99,IF(AND(NOT(OR(LEFT(TRIM(L3),3)="Yes",TRIM(L3)="Y",L3="Frozen Rate",L3="Frozen Plan",L3="Not able to Compare",L3="Info Not Avail",L3="NA",L3="")),AND(N3<>"No",N3<>"")),1,IF(NOT(OR(LEFT(TRIM(L3),3)="Yes",TRIM(L3)="Y",L3="Frozen Rate",L3="Frozen Plan",L3="Not able to Compare",L3="Info Not Avail",L3="NA",L3="")),2,IF(AND(N3<>"No",N3<>""),3,4)))) -> 99
A4: 45798 | B4: Phillips | C4: Crystal | D4: Young | E4: 85554 | F4: Opposed | G4: https://images.edocket.azcc.gov/docketpdf/E000044147.pdf | H4: 4823746138 | I4: R3-47 | J4: No | K4: No | L4: Yes | M4: No | N4: No | O4: Yes | P4: N | Q4: 45589 | R4: 0 | S4: 0 | T4: 0 | U4: 0 | V4: =IF(OR(LEFT(TRIM(L4),3)="Yes",TRIM(L4)="Y"),"✅ On Best Plan",IF(OR(L4="Frozen Rate",L4="Frozen Plan"),"❄ Frozen Rate",IF(OR(L4="Not able to Compare",L4="Info Not Avail",L4="NA",L4=""),"⚠ Unknown","❌ Not on Best Plan"))) -> ✅ On Best Plan | W4: =IFERROR(_xlfn.XLOOKUP(TEXT(H4,"0000000000"),'📞 Call Tracker'!A$2:A$2000,'📞 Call Tracker'!B$2:B$2000,""),"") -> Joaquin | X4: =IFERROR(_xlfn.XLOOKUP(TEXT(H4,"0000000000"),'📞 Call Tracker'!A$2:A$2000,'📞 Call Tracker'!C$2:C$2000,""),"") -> 45997 | Y4: =IFERROR(_xlfn.XLOOKUP(TEXT(H4,"0000000000"),'📞 Call Tracker'!A$2:A$2000,'📞 Call Tracker'!D$2:D$2000,""),"") -> YES | Z4: =IFERROR(_xlfn.XLOOKUP(TEXT(H4,"0000000000"),'📞 Call Tracker'!A$2:A$2000,'📞 Call Tracker'!E$2:E$2000,""),"") -> 0 | AA4: =IFERROR(_xlfn.XLOOKUP(TEXT(H4,"0000000000"),'📞 Call Tracker'!A$2:A$2000,'📞 Call Tracker'!F$2:F$2000,""),"") -> LEFT VOICE MAIL | AB4: =IF(OR(H4="",X4<>""),99,IF(AND(NOT(OR(LEFT(TRIM(L4),3)="Yes",TRIM(L4)="Y",L4="Frozen Rate",L4="Frozen Plan",L4="Not able to Compare",L4="Info Not Avail",L4="NA",L4="")),AND(N4<>"No",N4<>"")),1,IF(NOT(OR(LEFT(TRIM(L4),3)="Yes",TRIM(L4)="Y",L4="Frozen Rate",L4="Frozen Plan",L4="Not able to Compare",L4="Info Not Avail",L4="NA",L4="")),2,IF(AND(N4<>"No",N4<>""),3,4)))) -> 99
A5: 45799 | B5: Beame | C5: Sndney | D5: Unknown | E5: Unknown | F5: Opposed/Senior/fixed income | G5: https://images.edocket.azcc.gov/docketpdf/E000044169.pdf | H5: 8991140195 | I5: R-BASICL | J5: No | K5: No | L5: No - MEP R3-47 ($192.78) | M5: No | N5: No | O5: Yes | P5: 45964 | Q5: 45954 | R5: 11/03 - Customer agreed to change to their MEP | S5: 0 | T5: 0 | U5: Estimated savings $225.94/12 = $18.82 potential monthly savings on MEP | V5: =IF(OR(LEFT(TRIM(L5),3)="Yes",TRIM(L5)="Y"),"✅ On Best Plan",IF(OR(L5="Frozen Rate",L5="Frozen Plan"),"❄ Frozen Rate",IF(OR(L5="Not able to Compare",L5="Info Not Avail",L5="NA",L5=""),"⚠ Unknown","❌ Not on Best Plan"))) -> ❌ Not on Best Plan | W5: =IFERROR(_xlfn.XLOOKUP(TEXT(H5,"0000000000"),'📞 Call Tracker'!A$2:A$2000,'📞 Call Tracker'!B$2:B$2000,""),"") -> Joaquin | X5: =IFERROR(_xlfn.XLOOKUP(TEXT(H5,"0000000000"),'📞 Call Tracker'!A$2:A$2000,'📞 Call Tracker'!C$2:C$2000,""),"") -> 45997 | Y5: =IFERROR(_xlfn.XLOOKUP(TEXT(H5,"0000000000"),'📞 Call Tracker'!A$2:A$2000,'📞 Call Tracker'!D$2:D$2000,""),"") -> 0 | Z5: =IFERROR(_xlfn.XLOOKUP(TEXT(H5,"0000000000"),'📞 Call Tracker'!A$2:A$2000,'📞 Call Tracker'!E$2:E$2000,""),"") -> 0 | AA5: =IFERROR(_xlfn.XLOOKUP(TEXT(H5,"0000000000"),'📞 Call Tracker'!A$2:A$2000,'📞 Call Tracker'!F$2:F$2000,""),"") -> CLOSED ACCT 07/09/2015 | AB5: =IF(OR(H5="",X5<>""),99,IF(AND(NOT(OR(LEFT(TRIM(L5),3)="Yes",TRIM(L5)="Y",L5="Frozen Rate",L5="Frozen Plan",L5="Not able to Compare",L5="Info Not Avail",L5="NA",L5="")),AND(N5<>"No",N5<>"")),1,IF(NOT(OR(LEFT(TRIM(L5),3)="Yes",TRIM(L5)="Y",L5="Frozen Rate",L5="Frozen Plan",L5="Not able to Compare",L5="Info Not Avail",L5="NA",L5="")),2,IF(AND(N5<>"No",N5<>""),3,4)))) -> 99
A6: 45800 | B6: Scoggins | C6: Troy | D6: Phoenix | E6: 85009 | F6: Opposed | G6: https://images.edocket.azcc.gov/docketpdf/E000044282.pdf | H6: Unknown | I6: 0 | J6: 0 | K6: 0 | L6: 0 | M6: 0 | N6: 0 | O6: 0 | P6: 0 | Q6: 0 | R6: 0 | S6: 0 | T6: 0 | U6: Unable to locate account with name provided | V6: =IF(OR(LEFT(TRIM(L6),3)="Yes",TRIM(L6)="Y"),"✅ On Best Plan",IF(OR(L6="Frozen Rate",L6="Frozen Plan"),"❄ Frozen Rate",IF(OR(L6="Not able to Compare",L6="Info Not Avail",L6="NA",L6=""),"⚠ Unknown","❌ Not on Best Plan"))) -> ❌ Not on Best Plan | W6: =IFERROR(_xlfn.XLOOKUP(TEXT(H6,"0000000000"),'📞 Call Tracker'!A$2:A$2000,'📞 Call Tracker'!B$2:B$2000,""),"") | X6: =IFERROR(_xlfn.XLOOKUP(TEXT(H6,"0000000000"),'📞 Call Tracker'!A$2:A$2000,'📞 Call Tracker'!C$2:C$2000,""),"") | Y6: =IFERROR(_xlfn.XLOOKUP(TEXT(H6,"0000000000"),'📞 Call Tracker'!A$2:A$2000,'📞 Call Tracker'!D$2:D$2000,""),"") | Z6: =IFERROR(_xlfn.XLOOKUP(TEXT(H6,"0000000000"),'📞 Call Tracker'!A$2:A$2000,'📞 Call Tracker'!E$2:E$2000,""),"") | AA6: =IFERROR(_xlfn.XLOOKUP(TEXT(H6,"0000000000"),'📞 Call Tracker'!A$2:A$2000,'📞 Call Tracker'!F$2:F$2000,""),"") | AB6: =IF(OR(H6="",X6<>""),99,IF(AND(NOT(OR(LEFT(TRIM(L6),3)="Yes",TRIM(L6)="Y",L6="Frozen Rate",L6="Frozen Plan",L6="Not able to Compare",L6="Info Not Avail",L6="NA",L6="")),AND(N6<>"No",N6<>"")),1,IF(NOT(OR(LEFT(TRIM(L6),3)="Yes",TRIM(L6)="Y",L6="Frozen Rate",L6="Frozen Plan",L6="Not able to Compare",L6="Info Not Avail",L6="NA",L6="")),2,IF(AND(N6<>"No",N6<>""),3,4)))) -> 1
A7: 45804 | B7: Nuccio | C7: Tina | D7: Cave Creek | E7: 85331 | F7: Opposed | G7: https://images.edocket.azcc.gov/docketpdf/E000044298.pdf | H7: 5900820000 | I7: R3-47 | J7: No | K7: No | L7: Yes | M7: No | N7: No | O7: Yes | P7: N | Q7: 45954 | R7: 0 | S7: 0 | T7: 0 | U7: 0 | V7: =IF(OR(LEFT(TRIM(L7),3)="Yes",TRIM(L7)="Y"),"✅ On Best Plan",IF(OR(L7="Frozen Rate",L7="Frozen Plan"),"❄ Frozen Rate",IF(OR(L7="Not able to Compare",L7="Info Not Avail",L7="NA",L7=""),"⚠ Unknown","❌ Not on Best Plan"))) -> ✅ On Best Plan | W7: =IFERROR(_xlfn.XLOOKUP(TEXT(H7,"0000000000"),'📞 Call Tracker'!A$2:A$2000,'📞 Call Tracker'!B$2:B$2000,""),"") -> Michelle | X7: =IFERROR(_xlfn.XLOOKUP(TEXT(H7,"0000000000"),'📞 Call Tracker'!A$2:A$2000,'📞 Call Tracker'!C$2:C$2000,""),"") -> 46060 | Y7: =IFERROR(_xlfn.XLOOKUP(TEXT(H7,"0000000000"),'📞 Call Tracker'!A$2:A$2000,'📞 Call Tracker'!D$2:D$2000,""),"") -> YES | Z7: =IFERROR(_xlfn.XLOOKUP(TEXT(H7,"0000000000"),'📞 Call Tracker'!A$2:A$2000,'📞 Call Tracker'!E$2:E$2000,""),"") -> 0 | AA7: =IFERROR(_xlfn.XLOOKUP(TEXT(H7,"0000000000"),'📞 Call Tracker'!A$2:A$2000,'📞 Call Tracker'!F$2:F$2000,""),"") -> 0 | AB7: =IF(OR(H7="",X7<>""),99,IF(AND(NOT(OR(LEFT(TRIM(L7),3)="Yes",TRIM(L7)="Y",L7="Frozen Rate",L7="Frozen Plan",L7="Not able to Compare",L7="Info Not Avail",L7="NA",L7="")),AND(N7<>"No",N7<>"")),1,IF(NOT(OR(LEFT(TRIM(L7),3)="Yes",TRIM(L7)="Y",L7="Frozen Rate",L7="Frozen Plan",L7="Not able to Compare",L7="Info Not Avail",L7="NA",L7="")),2,IF(AND(N7<>"No",N7<>""),3,4)))) -> 99
